2023-11-21 15:50:42,848 [ERROR] Exception error
Traceback (most recent call last):
  File "/Users/leonovets/PycharmProjects/telegram_chats/src/api/chat.py", line 26, in get_chats
    chats = await ChatService().get_chats(uow=uow, filters=filters, limits=limits)
            ^^^^^^^^^^^^^^^^^^^^^^^^^^^^^^^^^^^^^^^^^^^^^^^^^^^^^^^^^^^^^^^^^^^^^^
  File "/Users/leonovets/PycharmProjects/telegram_chats/src/services/chat.py", line 18, in get_chats
    chats: list[ChatTable] = await uow.chat.get_all(filters=filters, limits=limits)
                                   ^^^^^^^^^^^^^^^^
  File "/Users/leonovets/miniconda3/lib/python3.11/typing.py", line 1287, in __getattr__
    return getattr(self.__origin__, attr)
           ^^^^^^^^^^^^^^^^^^^^^^^^^^^^^^
AttributeError: type object 'type' has no attribute 'get_all'
