2023-11-29 00:12:47,993 [ERROR] Exception error
Traceback (most recent call last):
  File "/Users/leonovets/Library/Caches/pypoetry/virtualenvs/pythonproject1-h3kM8LEl-py3.11/lib/python3.11/site-packages/sqlalchemy/dialects/postgresql/asyncpg.py", line 557, in _prepare_and_execute
    self._rows = await prepared_stmt.fetch(*parameters)
                 ^^^^^^^^^^^^^^^^^^^^^^^^^^^^^^^^^^^^^^
  File "/Users/leonovets/Library/Caches/pypoetry/virtualenvs/pythonproject1-h3kM8LEl-py3.11/lib/python3.11/site-packages/asyncpg/prepared_stmt.py", line 176, in fetch
    data = await self.__bind_execute(args, 0, timeout)
           ^^^^^^^^^^^^^^^^^^^^^^^^^^^^^^^^^^^^^^^^^^^
  File "/Users/leonovets/Library/Caches/pypoetry/virtualenvs/pythonproject1-h3kM8LEl-py3.11/lib/python3.11/site-packages/asyncpg/prepared_stmt.py", line 241, in __bind_execute
    data, status, _ = await self.__do_execute(
                      ^^^^^^^^^^^^^^^^^^^^^^^^
  File "/Users/leonovets/Library/Caches/pypoetry/virtualenvs/pythonproject1-h3kM8LEl-py3.11/lib/python3.11/site-packages/asyncpg/prepared_stmt.py", line 230, in __do_execute
    return await executor(protocol)
           ^^^^^^^^^^^^^^^^^^^^^^^^
  File "asyncpg/protocol/protocol.pyx", line 207, in bind_execute
asyncpg.exceptions.UniqueViolationError: duplicate key value violates unique constraint "chat_pkey"
DETAIL:  Key (id)=(0) already exists.

The above exception was the direct cause of the following exception:

Traceback (most recent call last):
  File "/Users/leonovets/Library/Caches/pypoetry/virtualenvs/pythonproject1-h3kM8LEl-py3.11/lib/python3.11/site-packages/sqlalchemy/engine/base.py", line 1969, in _exec_single_context
    self.dialect.do_execute(
  File "/Users/leonovets/Library/Caches/pypoetry/virtualenvs/pythonproject1-h3kM8LEl-py3.11/lib/python3.11/site-packages/sqlalchemy/engine/default.py", line 922, in do_execute
    cursor.execute(statement, parameters)
  File "/Users/leonovets/Library/Caches/pypoetry/virtualenvs/pythonproject1-h3kM8LEl-py3.11/lib/python3.11/site-packages/sqlalchemy/dialects/postgresql/asyncpg.py", line 591, in execute
    self._adapt_connection.await_(
  File "/Users/leonovets/Library/Caches/pypoetry/virtualenvs/pythonproject1-h3kM8LEl-py3.11/lib/python3.11/site-packages/sqlalchemy/util/_concurrency_py3k.py", line 125, in await_only
    return current.driver.switch(awaitable)  # type: ignore[no-any-return]
           ^^^^^^^^^^^^^^^^^^^^^^^^^^^^^^^^
  File "/Users/leonovets/Library/Caches/pypoetry/virtualenvs/pythonproject1-h3kM8LEl-py3.11/lib/python3.11/site-packages/sqlalchemy/util/_concurrency_py3k.py", line 185, in greenlet_spawn
    value = await result
            ^^^^^^^^^^^^
  File "/Users/leonovets/Library/Caches/pypoetry/virtualenvs/pythonproject1-h3kM8LEl-py3.11/lib/python3.11/site-packages/sqlalchemy/dialects/postgresql/asyncpg.py", line 569, in _prepare_and_execute
    self._handle_exception(error)
  File "/Users/leonovets/Library/Caches/pypoetry/virtualenvs/pythonproject1-h3kM8LEl-py3.11/lib/python3.11/site-packages/sqlalchemy/dialects/postgresql/asyncpg.py", line 520, in _handle_exception
    self._adapt_connection._handle_exception(error)
  File "/Users/leonovets/Library/Caches/pypoetry/virtualenvs/pythonproject1-h3kM8LEl-py3.11/lib/python3.11/site-packages/sqlalchemy/dialects/postgresql/asyncpg.py", line 808, in _handle_exception
    raise translated_error from error
sqlalchemy.dialects.postgresql.asyncpg.AsyncAdapt_asyncpg_dbapi.IntegrityError: <class 'asyncpg.exceptions.UniqueViolationError'>: duplicate key value violates unique constraint "chat_pkey"
DETAIL:  Key (id)=(0) already exists.

The above exception was the direct cause of the following exception:

Traceback (most recent call last):
  File "/Users/leonovets/PycharmProjects/telegram_chats/src/api/chat.py", line 50, in add_chats
    result = await ChatService().add_chats(uow=uow, chats=chats)
             ^^^^^^^^^^^^^^^^^^^^^^^^^^^^^^^^^^^^^^^^^^^^^^^^^^^
  File "/Users/leonovets/PycharmProjects/telegram_chats/src/services/chat.py", line 17, in add_chats
    result: list[ChatTable] = await uow.chat.add_all(values=[chat.model_dump() for chat in chats])
                              ^^^^^^^^^^^^^^^^^^^^^^^^^^^^^^^^^^^^^^^^^^^^^^^^^^^^^^^^^^^^^^^^^^^^
  File "/Users/leonovets/PycharmProjects/telegram_chats/src/utils/repository.py", line 49, in add_all
    result = await self.session.execute(stmt)
             ^^^^^^^^^^^^^^^^^^^^^^^^^^^^^^^^
  File "/Users/leonovets/Library/Caches/pypoetry/virtualenvs/pythonproject1-h3kM8LEl-py3.11/lib/python3.11/site-packages/sqlalchemy/ext/asyncio/session.py", line 455, in execute
    result = await greenlet_spawn(
             ^^^^^^^^^^^^^^^^^^^^^
  File "/Users/leonovets/Library/Caches/pypoetry/virtualenvs/pythonproject1-h3kM8LEl-py3.11/lib/python3.11/site-packages/sqlalchemy/util/_concurrency_py3k.py", line 190, in greenlet_spawn
    result = context.throw(*sys.exc_info())
             ^^^^^^^^^^^^^^^^^^^^^^^^^^^^^^
  File "/Users/leonovets/Library/Caches/pypoetry/virtualenvs/pythonproject1-h3kM8LEl-py3.11/lib/python3.11/site-packages/sqlalchemy/orm/session.py", line 2308, in execute
    return self._execute_internal(
           ^^^^^^^^^^^^^^^^^^^^^^^
  File "/Users/leonovets/Library/Caches/pypoetry/virtualenvs/pythonproject1-h3kM8LEl-py3.11/lib/python3.11/site-packages/sqlalchemy/orm/session.py", line 2190, in _execute_internal
    result: Result[Any] = compile_state_cls.orm_execute_statement(
                          ^^^^^^^^^^^^^^^^^^^^^^^^^^^^^^^^^^^^^^^^
  File "/Users/leonovets/Library/Caches/pypoetry/virtualenvs/pythonproject1-h3kM8LEl-py3.11/lib/python3.11/site-packages/sqlalchemy/orm/bulk_persistence.py", line 1276, in orm_execute_statement
    result = conn.execute(
             ^^^^^^^^^^^^^
  File "/Users/leonovets/Library/Caches/pypoetry/virtualenvs/pythonproject1-h3kM8LEl-py3.11/lib/python3.11/site-packages/sqlalchemy/engine/base.py", line 1416, in execute
    return meth(
           ^^^^^
  File "/Users/leonovets/Library/Caches/pypoetry/virtualenvs/pythonproject1-h3kM8LEl-py3.11/lib/python3.11/site-packages/sqlalchemy/sql/elements.py", line 516, in _execute_on_connection
    return connection._execute_clauseelement(
           ^^^^^^^^^^^^^^^^^^^^^^^^^^^^^^^^^^
  File "/Users/leonovets/Library/Caches/pypoetry/virtualenvs/pythonproject1-h3kM8LEl-py3.11/lib/python3.11/site-packages/sqlalchemy/engine/base.py", line 1639, in _execute_clauseelement
    ret = self._execute_context(
          ^^^^^^^^^^^^^^^^^^^^^^
  File "/Users/leonovets/Library/Caches/pypoetry/virtualenvs/pythonproject1-h3kM8LEl-py3.11/lib/python3.11/site-packages/sqlalchemy/engine/base.py", line 1848, in _execute_context
    return self._exec_single_context(
           ^^^^^^^^^^^^^^^^^^^^^^^^^^
  File "/Users/leonovets/Library/Caches/pypoetry/virtualenvs/pythonproject1-h3kM8LEl-py3.11/lib/python3.11/site-packages/sqlalchemy/engine/base.py", line 1988, in _exec_single_context
    self._handle_dbapi_exception(
  File "/Users/leonovets/Library/Caches/pypoetry/virtualenvs/pythonproject1-h3kM8LEl-py3.11/lib/python3.11/site-packages/sqlalchemy/engine/base.py", line 2343, in _handle_dbapi_exception
    raise sqlalchemy_exception.with_traceback(exc_info[2]) from e
  File "/Users/leonovets/Library/Caches/pypoetry/virtualenvs/pythonproject1-h3kM8LEl-py3.11/lib/python3.11/site-packages/sqlalchemy/engine/base.py", line 1969, in _exec_single_context
    self.dialect.do_execute(
  File "/Users/leonovets/Library/Caches/pypoetry/virtualenvs/pythonproject1-h3kM8LEl-py3.11/lib/python3.11/site-packages/sqlalchemy/engine/default.py", line 922, in do_execute
    cursor.execute(statement, parameters)
  File "/Users/leonovets/Library/Caches/pypoetry/virtualenvs/pythonproject1-h3kM8LEl-py3.11/lib/python3.11/site-packages/sqlalchemy/dialects/postgresql/asyncpg.py", line 591, in execute
    self._adapt_connection.await_(
  File "/Users/leonovets/Library/Caches/pypoetry/virtualenvs/pythonproject1-h3kM8LEl-py3.11/lib/python3.11/site-packages/sqlalchemy/util/_concurrency_py3k.py", line 125, in await_only
    return current.driver.switch(awaitable)  # type: ignore[no-any-return]
           ^^^^^^^^^^^^^^^^^^^^^^^^^^^^^^^^
  File "/Users/leonovets/Library/Caches/pypoetry/virtualenvs/pythonproject1-h3kM8LEl-py3.11/lib/python3.11/site-packages/sqlalchemy/util/_concurrency_py3k.py", line 185, in greenlet_spawn
    value = await result
            ^^^^^^^^^^^^
  File "/Users/leonovets/Library/Caches/pypoetry/virtualenvs/pythonproject1-h3kM8LEl-py3.11/lib/python3.11/site-packages/sqlalchemy/dialects/postgresql/asyncpg.py", line 569, in _prepare_and_execute
    self._handle_exception(error)
  File "/Users/leonovets/Library/Caches/pypoetry/virtualenvs/pythonproject1-h3kM8LEl-py3.11/lib/python3.11/site-packages/sqlalchemy/dialects/postgresql/asyncpg.py", line 520, in _handle_exception
    self._adapt_connection._handle_exception(error)
  File "/Users/leonovets/Library/Caches/pypoetry/virtualenvs/pythonproject1-h3kM8LEl-py3.11/lib/python3.11/site-packages/sqlalchemy/dialects/postgresql/asyncpg.py", line 808, in _handle_exception
    raise translated_error from error
sqlalchemy.exc.IntegrityError: (sqlalchemy.dialects.postgresql.asyncpg.IntegrityError) <class 'asyncpg.exceptions.UniqueViolationError'>: duplicate key value violates unique constraint "chat_pkey"
DETAIL:  Key (id)=(0) already exists.
[SQL: INSERT INTO chat (id, username, invite_link, members_count, title, description, is_verified, is_restricted, is_scam, is_fake, is_forum, is_moderated, is_closed) VALUES ($1::INTEGER, $2::VARCHAR, $3::VARCHAR, $4::INTEGER, $5::VARCHAR, $6::VARCHAR, $7::BOOLEAN, $8::BOOLEAN, $9::BOOLEAN, $10::BOOLEAN, $11::BOOLEAN, $12::BOOLEAN, $13::BOOLEAN) RETURNING chat.id, chat.username, chat.invite_link, chat.members_count, chat.title, chat.description, chat.is_verified, chat.is_restricted, chat.is_scam, chat.is_fake, chat.is_forum, chat.is_moderated, chat.is_closed, chat.updated_at]
[parameters: (0, 'string', 'string', 0, 'string', None, False, False, False, False, False, False, False)]
(Background on this error at: https://sqlalche.me/e/20/gkpj)
2023-11-29 00:12:59,662 [ERROR] Exception error
Traceback (most recent call last):
  File "/Users/leonovets/PycharmProjects/telegram_chats/src/api/chat.py", line 50, in add_chats
    result = await ChatService().add_chats(uow=uow, chats=chats)
             ^^^^^^^^^^^^^^^^^^^^^^^^^^^^^^^^^^^^^^^^^^^^^^^^^^^
  File "/Users/leonovets/PycharmProjects/telegram_chats/src/services/chat.py", line 19, in add_chats
    return ChatModel(**result.__dict__)
                       ^^^^^^^^^^^^^^^
AttributeError: 'list' object has no attribute '__dict__'
2023-11-29 00:13:50,539 [ERROR] Exception error
Traceback (most recent call last):
  File "/Users/leonovets/Library/Caches/pypoetry/virtualenvs/pythonproject1-h3kM8LEl-py3.11/lib/python3.11/site-packages/sqlalchemy/dialects/postgresql/asyncpg.py", line 557, in _prepare_and_execute
    self._rows = await prepared_stmt.fetch(*parameters)
                 ^^^^^^^^^^^^^^^^^^^^^^^^^^^^^^^^^^^^^^
  File "/Users/leonovets/Library/Caches/pypoetry/virtualenvs/pythonproject1-h3kM8LEl-py3.11/lib/python3.11/site-packages/asyncpg/prepared_stmt.py", line 176, in fetch
    data = await self.__bind_execute(args, 0, timeout)
           ^^^^^^^^^^^^^^^^^^^^^^^^^^^^^^^^^^^^^^^^^^^
  File "/Users/leonovets/Library/Caches/pypoetry/virtualenvs/pythonproject1-h3kM8LEl-py3.11/lib/python3.11/site-packages/asyncpg/prepared_stmt.py", line 241, in __bind_execute
    data, status, _ = await self.__do_execute(
                      ^^^^^^^^^^^^^^^^^^^^^^^^
  File "/Users/leonovets/Library/Caches/pypoetry/virtualenvs/pythonproject1-h3kM8LEl-py3.11/lib/python3.11/site-packages/asyncpg/prepared_stmt.py", line 230, in __do_execute
    return await executor(protocol)
           ^^^^^^^^^^^^^^^^^^^^^^^^
  File "asyncpg/protocol/protocol.pyx", line 207, in bind_execute
asyncpg.exceptions.UniqueViolationError: duplicate key value violates unique constraint "chat_pkey"
DETAIL:  Key (id)=(10) already exists.

The above exception was the direct cause of the following exception:

Traceback (most recent call last):
  File "/Users/leonovets/Library/Caches/pypoetry/virtualenvs/pythonproject1-h3kM8LEl-py3.11/lib/python3.11/site-packages/sqlalchemy/engine/base.py", line 1969, in _exec_single_context
    self.dialect.do_execute(
  File "/Users/leonovets/Library/Caches/pypoetry/virtualenvs/pythonproject1-h3kM8LEl-py3.11/lib/python3.11/site-packages/sqlalchemy/engine/default.py", line 922, in do_execute
    cursor.execute(statement, parameters)
  File "/Users/leonovets/Library/Caches/pypoetry/virtualenvs/pythonproject1-h3kM8LEl-py3.11/lib/python3.11/site-packages/sqlalchemy/dialects/postgresql/asyncpg.py", line 591, in execute
    self._adapt_connection.await_(
  File "/Users/leonovets/Library/Caches/pypoetry/virtualenvs/pythonproject1-h3kM8LEl-py3.11/lib/python3.11/site-packages/sqlalchemy/util/_concurrency_py3k.py", line 125, in await_only
    return current.driver.switch(awaitable)  # type: ignore[no-any-return]
           ^^^^^^^^^^^^^^^^^^^^^^^^^^^^^^^^
  File "/Users/leonovets/Library/Caches/pypoetry/virtualenvs/pythonproject1-h3kM8LEl-py3.11/lib/python3.11/site-packages/sqlalchemy/util/_concurrency_py3k.py", line 185, in greenlet_spawn
    value = await result
            ^^^^^^^^^^^^
  File "/Users/leonovets/Library/Caches/pypoetry/virtualenvs/pythonproject1-h3kM8LEl-py3.11/lib/python3.11/site-packages/sqlalchemy/dialects/postgresql/asyncpg.py", line 569, in _prepare_and_execute
    self._handle_exception(error)
  File "/Users/leonovets/Library/Caches/pypoetry/virtualenvs/pythonproject1-h3kM8LEl-py3.11/lib/python3.11/site-packages/sqlalchemy/dialects/postgresql/asyncpg.py", line 520, in _handle_exception
    self._adapt_connection._handle_exception(error)
  File "/Users/leonovets/Library/Caches/pypoetry/virtualenvs/pythonproject1-h3kM8LEl-py3.11/lib/python3.11/site-packages/sqlalchemy/dialects/postgresql/asyncpg.py", line 808, in _handle_exception
    raise translated_error from error
sqlalchemy.dialects.postgresql.asyncpg.AsyncAdapt_asyncpg_dbapi.IntegrityError: <class 'asyncpg.exceptions.UniqueViolationError'>: duplicate key value violates unique constraint "chat_pkey"
DETAIL:  Key (id)=(10) already exists.

The above exception was the direct cause of the following exception:

Traceback (most recent call last):
  File "/Users/leonovets/PycharmProjects/telegram_chats/src/api/chat.py", line 50, in add_chats
    result = await ChatService().add_chats(uow=uow, chats=chats)
             ^^^^^^^^^^^^^^^^^^^^^^^^^^^^^^^^^^^^^^^^^^^^^^^^^^^
  File "/Users/leonovets/PycharmProjects/telegram_chats/src/services/chat.py", line 17, in add_chats
    result: list[ChatTable] = await uow.chat.add_all(values=[chat.model_dump() for chat in chats])
                              ^^^^^^^^^^^^^^^^^^^^^^^^^^^^^^^^^^^^^^^^^^^^^^^^^^^^^^^^^^^^^^^^^^^^
  File "/Users/leonovets/PycharmProjects/telegram_chats/src/utils/repository.py", line 49, in add_all
    result = await self.session.execute(stmt)
             ^^^^^^^^^^^^^^^^^^^^^^^^^^^^^^^^
  File "/Users/leonovets/Library/Caches/pypoetry/virtualenvs/pythonproject1-h3kM8LEl-py3.11/lib/python3.11/site-packages/sqlalchemy/ext/asyncio/session.py", line 455, in execute
    result = await greenlet_spawn(
             ^^^^^^^^^^^^^^^^^^^^^
  File "/Users/leonovets/Library/Caches/pypoetry/virtualenvs/pythonproject1-h3kM8LEl-py3.11/lib/python3.11/site-packages/sqlalchemy/util/_concurrency_py3k.py", line 190, in greenlet_spawn
    result = context.throw(*sys.exc_info())
             ^^^^^^^^^^^^^^^^^^^^^^^^^^^^^^
  File "/Users/leonovets/Library/Caches/pypoetry/virtualenvs/pythonproject1-h3kM8LEl-py3.11/lib/python3.11/site-packages/sqlalchemy/orm/session.py", line 2308, in execute
    return self._execute_internal(
           ^^^^^^^^^^^^^^^^^^^^^^^
  File "/Users/leonovets/Library/Caches/pypoetry/virtualenvs/pythonproject1-h3kM8LEl-py3.11/lib/python3.11/site-packages/sqlalchemy/orm/session.py", line 2190, in _execute_internal
    result: Result[Any] = compile_state_cls.orm_execute_statement(
                          ^^^^^^^^^^^^^^^^^^^^^^^^^^^^^^^^^^^^^^^^
  File "/Users/leonovets/Library/Caches/pypoetry/virtualenvs/pythonproject1-h3kM8LEl-py3.11/lib/python3.11/site-packages/sqlalchemy/orm/bulk_persistence.py", line 1276, in orm_execute_statement
    result = conn.execute(
             ^^^^^^^^^^^^^
  File "/Users/leonovets/Library/Caches/pypoetry/virtualenvs/pythonproject1-h3kM8LEl-py3.11/lib/python3.11/site-packages/sqlalchemy/engine/base.py", line 1416, in execute
    return meth(
           ^^^^^
  File "/Users/leonovets/Library/Caches/pypoetry/virtualenvs/pythonproject1-h3kM8LEl-py3.11/lib/python3.11/site-packages/sqlalchemy/sql/elements.py", line 516, in _execute_on_connection
    return connection._execute_clauseelement(
           ^^^^^^^^^^^^^^^^^^^^^^^^^^^^^^^^^^
  File "/Users/leonovets/Library/Caches/pypoetry/virtualenvs/pythonproject1-h3kM8LEl-py3.11/lib/python3.11/site-packages/sqlalchemy/engine/base.py", line 1639, in _execute_clauseelement
    ret = self._execute_context(
          ^^^^^^^^^^^^^^^^^^^^^^
  File "/Users/leonovets/Library/Caches/pypoetry/virtualenvs/pythonproject1-h3kM8LEl-py3.11/lib/python3.11/site-packages/sqlalchemy/engine/base.py", line 1848, in _execute_context
    return self._exec_single_context(
           ^^^^^^^^^^^^^^^^^^^^^^^^^^
  File "/Users/leonovets/Library/Caches/pypoetry/virtualenvs/pythonproject1-h3kM8LEl-py3.11/lib/python3.11/site-packages/sqlalchemy/engine/base.py", line 1988, in _exec_single_context
    self._handle_dbapi_exception(
  File "/Users/leonovets/Library/Caches/pypoetry/virtualenvs/pythonproject1-h3kM8LEl-py3.11/lib/python3.11/site-packages/sqlalchemy/engine/base.py", line 2343, in _handle_dbapi_exception
    raise sqlalchemy_exception.with_traceback(exc_info[2]) from e
  File "/Users/leonovets/Library/Caches/pypoetry/virtualenvs/pythonproject1-h3kM8LEl-py3.11/lib/python3.11/site-packages/sqlalchemy/engine/base.py", line 1969, in _exec_single_context
    self.dialect.do_execute(
  File "/Users/leonovets/Library/Caches/pypoetry/virtualenvs/pythonproject1-h3kM8LEl-py3.11/lib/python3.11/site-packages/sqlalchemy/engine/default.py", line 922, in do_execute
    cursor.execute(statement, parameters)
  File "/Users/leonovets/Library/Caches/pypoetry/virtualenvs/pythonproject1-h3kM8LEl-py3.11/lib/python3.11/site-packages/sqlalchemy/dialects/postgresql/asyncpg.py", line 591, in execute
    self._adapt_connection.await_(
  File "/Users/leonovets/Library/Caches/pypoetry/virtualenvs/pythonproject1-h3kM8LEl-py3.11/lib/python3.11/site-packages/sqlalchemy/util/_concurrency_py3k.py", line 125, in await_only
    return current.driver.switch(awaitable)  # type: ignore[no-any-return]
           ^^^^^^^^^^^^^^^^^^^^^^^^^^^^^^^^
  File "/Users/leonovets/Library/Caches/pypoetry/virtualenvs/pythonproject1-h3kM8LEl-py3.11/lib/python3.11/site-packages/sqlalchemy/util/_concurrency_py3k.py", line 185, in greenlet_spawn
    value = await result
            ^^^^^^^^^^^^
  File "/Users/leonovets/Library/Caches/pypoetry/virtualenvs/pythonproject1-h3kM8LEl-py3.11/lib/python3.11/site-packages/sqlalchemy/dialects/postgresql/asyncpg.py", line 569, in _prepare_and_execute
    self._handle_exception(error)
  File "/Users/leonovets/Library/Caches/pypoetry/virtualenvs/pythonproject1-h3kM8LEl-py3.11/lib/python3.11/site-packages/sqlalchemy/dialects/postgresql/asyncpg.py", line 520, in _handle_exception
    self._adapt_connection._handle_exception(error)
  File "/Users/leonovets/Library/Caches/pypoetry/virtualenvs/pythonproject1-h3kM8LEl-py3.11/lib/python3.11/site-packages/sqlalchemy/dialects/postgresql/asyncpg.py", line 808, in _handle_exception
    raise translated_error from error
sqlalchemy.exc.IntegrityError: (sqlalchemy.dialects.postgresql.asyncpg.IntegrityError) <class 'asyncpg.exceptions.UniqueViolationError'>: duplicate key value violates unique constraint "chat_pkey"
DETAIL:  Key (id)=(10) already exists.
[SQL: INSERT INTO chat (id, username, invite_link, members_count, title, description, is_verified, is_restricted, is_scam, is_fake, is_forum, is_moderated, is_closed) VALUES ($1::INTEGER, $2::VARCHAR, $3::VARCHAR, $4::INTEGER, $5::VARCHAR, $6::VARCHAR, $7::BOOLEAN, $8::BOOLEAN, $9::BOOLEAN, $10::BOOLEAN, $11::BOOLEAN, $12::BOOLEAN, $13::BOOLEAN) RETURNING chat.id, chat.username, chat.invite_link, chat.members_count, chat.title, chat.description, chat.is_verified, chat.is_restricted, chat.is_scam, chat.is_fake, chat.is_forum, chat.is_moderated, chat.is_closed, chat.updated_at]
[parameters: (10, 'string', 'string', 0, 'string', None, False, False, False, False, False, False, False)]
(Background on this error at: https://sqlalche.me/e/20/gkpj)
